Unexpected exception in keepalive ping task
Traceback (most recent call last):
  File "/usr/lib64/python3.6/site-packages/websockets/protocol.py", line 674, in transfer_data
    message = yield from self.read_message()
  File "/usr/lib64/python3.6/site-packages/websockets/protocol.py", line 742, in read_message
    frame = yield from self.read_data_frame(max_size=self.max_size)
  File "/usr/lib64/python3.6/site-packages/websockets/protocol.py", line 815, in read_data_frame
    frame = yield from self.read_frame(max_size)
  File "/usr/lib64/python3.6/site-packages/websockets/protocol.py", line 884, in read_frame
    extensions=self.extensions,
  File "/usr/lib64/python3.6/site-packages/websockets/framing.py", line 99, in read
    data = yield from reader(2)
  File "/usr/lib64/python3.6/asyncio/streams.py", line 674, in readexactly
    yield from self._wait_for_data('readexactly')
  File "/usr/lib64/python3.6/asyncio/streams.py", line 464, in _wait_for_data
    yield from self._waiter
  File "/usr/lib64/python3.6/asyncio/selector_events.py", line 725, in _read_ready
    data = self._sock.recv(self.max_size)
ConnectionResetError: [Errno 104] Connection reset by peer

The above exception was the direct cause of the following exception:

Traceback (most recent call last):
  File "/usr/lib64/python3.6/site-packages/websockets/protocol.py", line 984, in keepalive_ping
    ping_waiter = yield from self.ping()
  File "/usr/lib64/python3.6/site-packages/websockets/protocol.py", line 583, in ping
    yield from self.ensure_open()
  File "/usr/lib64/python3.6/site-packages/websockets/protocol.py", line 646, in ensure_open
    ) from self.transfer_data_exc
websockets.exceptions.ConnectionClosed: WebSocket connection is closed: code = 1006 (connection closed abnormally [internal]), no reason
Unexpected exception in keepalive ping task
Traceback (most recent call last):
  File "/usr/lib64/python3.6/site-packages/websockets/protocol.py", line 984, in keepalive_ping
    ping_waiter = yield from self.ping()
  File "/usr/lib64/python3.6/site-packages/websockets/protocol.py", line 583, in ping
    yield from self.ensure_open()
  File "/usr/lib64/python3.6/site-packages/websockets/protocol.py", line 658, in ensure_open
    ) from self.transfer_data_exc
websockets.exceptions.ConnectionClosed: WebSocket connection is closed: code = 1001 (going away), reason = CloudFlare WebSocket proxy restarting
Unexpected exception in keepalive ping task
Traceback (most recent call last):
  File "/usr/lib64/python3.6/site-packages/websockets/protocol.py", line 984, in keepalive_ping
    ping_waiter = yield from self.ping()
  File "/usr/lib64/python3.6/site-packages/websockets/protocol.py", line 583, in ping
    yield from self.ensure_open()
  File "/usr/lib64/python3.6/site-packages/websockets/protocol.py", line 646, in ensure_open
    ) from self.transfer_data_exc
websockets.exceptions.ConnectionClosed: WebSocket connection is closed: code = 1001 (going away), reason = CloudFlare WebSocket proxy restarting
Unexpected exception in keepalive ping task
Traceback (most recent call last):
  File "/usr/lib64/python3.6/site-packages/websockets/protocol.py", line 989, in keepalive_ping
    ping_waiter, self.ping_timeout, loop=self.loop
  File "/usr/lib64/python3.6/asyncio/tasks.py", line 358, in wait_for
    return fut.result()
websockets.exceptions.ConnectionClosed: WebSocket connection is closed: code = 1006 (connection closed abnormally [internal]), no reason
Unexpected exception in keepalive ping task
Traceback (most recent call last):
  File "/usr/lib64/python3.6/site-packages/websockets/protocol.py", line 989, in keepalive_ping
    ping_waiter, self.ping_timeout, loop=self.loop
  File "/usr/lib64/python3.6/asyncio/tasks.py", line 358, in wait_for
    return fut.result()
websockets.exceptions.ConnectionClosed: WebSocket connection is closed: code = 1006 (connection closed abnormally [internal]), no reason
Unexpected exception in keepalive ping task
Traceback (most recent call last):
  File "/usr/lib64/python3.6/site-packages/websockets/protocol.py", line 674, in transfer_data
    message = yield from self.read_message()
  File "/usr/lib64/python3.6/site-packages/websockets/protocol.py", line 742, in read_message
    frame = yield from self.read_data_frame(max_size=self.max_size)
  File "/usr/lib64/python3.6/site-packages/websockets/protocol.py", line 815, in read_data_frame
    frame = yield from self.read_frame(max_size)
  File "/usr/lib64/python3.6/site-packages/websockets/protocol.py", line 884, in read_frame
    extensions=self.extensions,
  File "/usr/lib64/python3.6/site-packages/websockets/framing.py", line 99, in read
    data = yield from reader(2)
  File "/usr/lib64/python3.6/asyncio/streams.py", line 674, in readexactly
    yield from self._wait_for_data('readexactly')
  File "/usr/lib64/python3.6/asyncio/streams.py", line 464, in _wait_for_data
    yield from self._waiter
  File "/usr/lib64/python3.6/asyncio/selector_events.py", line 725, in _read_ready
    data = self._sock.recv(self.max_size)
ConnectionResetError: [Errno 104] Connection reset by peer

The above exception was the direct cause of the following exception:

Traceback (most recent call last):
  File "/usr/lib64/python3.6/site-packages/websockets/protocol.py", line 984, in keepalive_ping
    ping_waiter = yield from self.ping()
  File "/usr/lib64/python3.6/site-packages/websockets/protocol.py", line 583, in ping
    yield from self.ensure_open()
  File "/usr/lib64/python3.6/site-packages/websockets/protocol.py", line 646, in ensure_open
    ) from self.transfer_data_exc
websockets.exceptions.ConnectionClosed: WebSocket connection is closed: code = 1006 (connection closed abnormally [internal]), no reason
Unexpected exception in keepalive ping task
Traceback (most recent call last):
  File "/usr/lib64/python3.6/site-packages/websockets/protocol.py", line 989, in keepalive_ping
    ping_waiter, self.ping_timeout, loop=self.loop
  File "/usr/lib64/python3.6/asyncio/tasks.py", line 358, in wait_for
    return fut.result()
websockets.exceptions.ConnectionClosed: WebSocket connection is closed: code = 1006 (connection closed abnormally [internal]), no reason
ログインしました
Traceback (most recent call last):
  File "discordbot1.py", line 98, in <module>
    client.run(os.environ["MC_BOT_KEY"])
  File "/usr/lib/python3.6/site-packages/discord/client.py", line 519, in run
    self.loop.run_until_complete(self.start(*args, **kwargs))
  File "/usr/lib64/python3.6/asyncio/base_events.py", line 473, in run_until_complete
    return future.result()
  File "/usr/lib/python3.6/site-packages/discord/client.py", line 491, in start
    yield from self.connect()
  File "/usr/lib/python3.6/site-packages/discord/client.py", line 448, in connect
    yield from self.ws.poll_event()
  File "/usr/lib/python3.6/site-packages/discord/gateway.py", line 430, in poll_event
    msg = yield from self.recv()
  File "/usr/lib64/python3.6/site-packages/websockets/protocol.py", line 434, in recv
    yield from self.ensure_open()
  File "/usr/lib64/python3.6/site-packages/websockets/protocol.py", line 655, in ensure_open
    yield from asyncio.shield(self.close_connection_task)
  File "/usr/lib/python3.6/site-packages/discord/gateway.py", line 522, in close_connection
    yield from super().close_connection(force=force)
TypeError: close_connection() got an unexpected keyword argument 'force'
